#include <iostream>

int main()
{
  try {
    return 0;
  }
  catch (const std::exception& e) {
    std::cerr << e.what() << '\n';
    return 1;
  }
}